Workbook

Sheet 词根拆分
A1: 词根 | B1: 搜索人气 | F1: {=INDEX($D$1:$D$861,ROW()*2)} -> 手链 | G1: {=INDEX($D$1:$D$861,ROW()*4-1)} -> 1234.43 | H1: =G1*10000 -> 12344300
A2: 手链 | B2: 12344300 | D2: 手链 | F2: {=INDEX($D$1:$D$861,ROW()*2)} -> 手串 | G2: {=INDEX($D$1:$D$861,ROW()*4-1)} -> 166.37 | H2: =G2*10000 -> 1663700
A3: 手串 | B3: 5805400 | D3: 1234.43 | F3: {=INDEX($D$1:$D$861,ROW()*2)} -> 朱砂 | G3: {=INDEX($D$1:$D$861,ROW()*4-1)} -> 75.49 | H3: =G3*10000 -> 754900
A4: 朱砂 | B4: 1663700 | D4: 手串 | F4: {=INDEX($D$1:$D$861,ROW()*2)} -> 珍珠 | G4: {=INDEX($D$1:$D$861,ROW()*4-1)} -> 56.32 | H4: =G4*10000 -> 563200
A5: 珍珠 | B5: 1034200 | D5: 580.54 | F5: {=INDEX($D$1:$D$861,ROW()*2)} -> 水晶 | G5: {=INDEX($D$1:$D$861,ROW()*4-1)} -> 51.6 | H5: =G5*10000 -> 516000
A6: 水晶 | B6: 754900 | D6: 朱砂 | F6: {=INDEX($D$1:$D$861,ROW()*2)} -> redline | G6: {=INDEX($D$1:$D$861,ROW()*4-1)} -> 41.54 | H6: =G6*10000 -> 415400
A7: redline | B7: 690500 | D7: 166.37 | F7: {=INDEX($D$1:$D$861,ROW()*2)} -> 手绳 | G7: {=INDEX($D$1:$D$861,ROW()*4-1)} -> 40.03 | H7: =G7*10000 -> 400300
A8: 手绳 | B8: 563200 | D8: 珍珠 | F8: {=INDEX($D$1:$D$861,ROW()*2)} -> 女 | G8: {=INDEX($D$1:$D$861,ROW()*4-1)} -> 38.16 | H8: =G8*10000 -> 381600
A9: 女 | B9: 545000 | D9: 103.42 | F9: {=INDEX($D$1:$D$861,ROW()*2)} -> 红绳 | G9: {=INDEX($D$1:$D$861,ROW()*4-1)} -> 35.81 | H9: =G9*10000 -> 358100
A10: 红绳 | B10: 516000 | D10: 水晶 | F10: {=INDEX($D$1:$D$861,ROW()*2)} -> 银 | G10: {=INDEX($D$1:$D$861,ROW()*4-1)} -> 33.99 | H10: =G10*10000 -> 339900
A11: 银 | B11: 451500 | D11: 75.49 | F11: {=INDEX($D$1:$D$861,ROW()*2)} -> 潘多拉 | G11: {=INDEX($D$1:$D$861,ROW()*4-1)} -> 30.42 | H11: =G11*10000 -> 304200
A12: 潘多拉 | B12: 415400 | D12: redline | F12: {=INDEX($D$1:$D$861,ROW()*2)} -> 女生 | G12: {=INDEX($D$1:$D$861,ROW()*4-1)} -> 29.61 | H12: =G12*10000 -> 296100
A13: 女生 | B13: 401300 | D13: 69.05 | F13: {=INDEX($D$1:$D$861,ROW()*2)} -> 女款 | G13: {=INDEX($D$1:$D$861,ROW()*4-1)} -> 29.35 | H13: =G13*10000 -> 293500
A14: 女款 | B14: 400300 | D14: 手绳 | F14: {=INDEX($D$1:$D$861,ROW()*2)} -> 四叶草 | G14: {=INDEX($D$1:$D$861,ROW()*4-1)} -> 27.16 | H14: =G14*10000 -> 271600
A15: 四叶草 | B15: 384600 | D15: 56.32 | F15: {=INDEX($D$1:$D$861,ROW()*2)} -> 情侣 | G15: {=INDEX($D$1:$D$861,ROW()*4-1)} -> 26.06 | H15: =G15*10000 -> 260600
A16: 情侣 | B16: 381600 | D16: 女 | F16: {=INDEX($D$1:$D$861,ROW()*2)} -> 串珠 | G16: {=INDEX($D$1:$D$861,ROW()*4-1)} -> 23.54 | H16: =G16*10000 -> 235400
A17: 串珠 | B17: 377100 | D17: 54.5 | F17: {=INDEX($D$1:$D$861,ROW()*2)} -> 小众 | G17: {=INDEX($D$1:$D$861,ROW()*4-1)} -> 23.16 | H17: =G17*10000 -> 231600
A18: 小众 | B18: 358100 | D18: 红绳 | F18: {=INDEX($D$1:$D$861,ROW()*2)} -> 绿松石 | G18: {=INDEX($D$1:$D$861,ROW()*4-1)} -> 21.45 | H18: =G18*10000 -> 214500
A19: 绿松石 | B19: 352200 | D19: 51.6 | F19: {=INDEX($D$1:$D$861,ROW()*2)} -> 纯银 | G19: {=INDEX($D$1:$D$861,ROW()*4-1)} -> 20.13 | H19: =G19*10000 -> 201300
A20: 纯银 | B20: 339900 | D20: 银 | F20: {=INDEX($D$1:$D$861,ROW()*2)} -> 旗舰店 | G20: {=INDEX($D$1:$D$861,ROW()*4-1)} -> 19.21 | H20: =G20*10000 -> 192100
A21: 旗舰店 | B21: 338800 | D21: 45.15 | F21: {=INDEX($D$1:$D$861,ROW()*2)} -> 官方 | G21: {=INDEX($D$1:$D$861,ROW()*4-1)} -> 17.46 | H21: =G21*10000 -> 174600
A22: 官方 | B22: 304200 | D22: 潘多拉 | F22: {=INDEX($D$1:$D$861,ROW()*2)} -> 男士 | G22: {=INDEX($D$1:$D$861,ROW()*4-1)} -> 16.55 | H22: =G22*10000 -> 165500
A23: 男士 | B23: 296600 | D23: 41.54 | F23: {=INDEX($D$1:$D$861,ROW()*2)} -> 天然 | G23: {=INDEX($D$1:$D$861,ROW()*4-1)} -> 16.36 | H23: =G23*10000 -> 163600
A24: 天然 | B24: 296100 | D24: 女生 | F24: {=INDEX($D$1:$D$861,ROW()*2)} -> 紫水晶 | G24: {=INDEX($D$1:$D$861,ROW()*4-1)} -> 15.03 | H24: =G24*10000 -> 150300
A25: 紫水晶 | B25: 295700 | D25: 40.13 | F25: {=INDEX($D$1:$D$861,ROW()*2)} -> 男款 | G25: {=INDEX($D$1:$D$861,ROW()*4-1)} -> 14.7 | H25: =G25*10000 -> 147000
A26: 男款 | B26: 293500 | D26: 女款 | F26: {=INDEX($D$1:$D$861,ROW()*2)} -> 碧玺 | G26: {=INDEX($D$1:$D$861,ROW()*4-1)} -> 13.63 | H26: =G26*10000 -> 136300
A27: 碧玺 | B27: 285500 | D27: 40.03 | F27: {=INDEX($D$1:$D$861,ROW()*2)} -> 情绪稳定 | G27: {=INDEX($D$1:$D$861,ROW()*4-1)} -> 12.58 | H27: =G27*10000 -> 125800
A28: 情绪稳定 | B28: 271600 | D28: 四叶草 | F28: {=INDEX($D$1:$D$861,ROW()*2)} -> 黑曜石 | G28: {=INDEX($D$1:$D$861,ROW()*4-1)} -> 10.85 | H28: =G28*10000 -> 108500
A29: 黑曜石 | B29: 261400 | D29: 38.46 | F29: {=INDEX($D$1:$D$861,ROW()*2)} -> 玛瑙 | G29: {=INDEX($D$1:$D$861,ROW()*4-1)} -> 10.23 | H29: =G29*10000 -> 102300
A30: 玛瑙 | B30: 260600 | D30: 情侣 | F30: {=INDEX($D$1:$D$861,ROW()*2)} -> 石榴石 | G30: {=INDEX($D$1:$D$861,ROW()*4-1)} -> 9.71 | H30: =G30*10000 -> 97100
A31: 石榴石 | B31: 248900 | D31: 38.16 | F31: {=INDEX($D$1:$D$861,ROW()*2)} -> 精致 | G31: {=INDEX($D$1:$D$861,ROW()*4-1)} -> 9.53 | H31: =G31*10000 -> 95300
A32: 精致 | B32: 235400 | D32: 串珠 | F32: {=INDEX($D$1:$D$861,ROW()*2)} -> 男生 | G32: {=INDEX($D$1:$D$861,ROW()*4-1)} -> 9.4 | H32: =G32*10000 -> 94000
A33: 男生 | B33: 234800 | D33: 37.71 | F33: {=INDEX($D$1:$D$861,ROW()*2)} -> 南红 | G33: {=INDEX($D$1:$D$861,ROW()*4-1)} -> 9.16 | H33: =G33*10000 -> 91600
A34: 南红 | B34: 231600 | D34: 小众 | F34: {=INDEX($D$1:$D$861,ROW()*2)} -> 男 | G34: {=INDEX($D$1:$D$861,ROW()*4-1)} -> 8.91 | H34: =G34*10000 -> 89100
A35: 男 | B35: 217300 | D35: 35.81 | F35: {=INDEX($D$1:$D$861,ROW()*2)} -> 编织绳 | G35: {=INDEX($D$1:$D$861,ROW()*4-1)} -> 8.64 | H35: =G35*10000 -> 86400
A36: 编织绳 | B36: 214500 | D36: 绿松石 | F36: {=INDEX($D$1:$D$861,ROW()*2)} -> 佛珠 | G36: {=INDEX($D$1:$D$861,ROW()*4-1)} -> 8.42 | H36: =G36*10000 -> 84200
A37: 佛珠 | B37: 207600 | D37: 35.22 | F37: {=INDEX($D$1:$D$861,ROW()*2)} -> 黄水晶 | G37: {=INDEX($D$1:$D$861,ROW()*4-1)} -> 8.38 | H37: =G37*10000 -> 83800
A38: 黄水晶 | B38: 201300 | D38: 纯银 | F38: {=INDEX($D$1:$D$861,ROW()*2)} -> 轻奢 | G38: {=INDEX($D$1:$D$861,ROW()*4-1)} -> 7.77 | H38: =G38*10000 -> 77700
A39: 轻奢 | B39: 199700 | D39: 33.99 | F39: {=INDEX($D$1:$D$861,ROW()*2)} -> 小叶紫檀 | G39: {=INDEX($D$1:$D$861,ROW()*4-1)} -> 7.5 | H39: =G39*10000 -> 75000
A40: 小叶紫檀 | B40: 192100 | D40: 旗舰店 | F40: {=INDEX($D$1:$D$861,ROW()*2)} -> 正品 | G40: {=INDEX($D$1:$D$861,ROW()*4-1)} -> 7 | H40: =G40*10000 -> 70000
...

Sheet 关键词需求归类
A1: 词根 | B1: 搜索人气 | C1: 需求分类
A2: 手链 | B2: 12344300 | C2: 品类需求
A3: 手串 | B3: 5805400 | C3: 品类需求
A4: 朱砂 | B4: 1663700 | C4: 属性需求
A5: 珍珠 | B5: 1034200 | C5: 属性需求
A6: 水晶 | B6: 754900 | C6: 属性需求
A7: redline | B7: 690500 | C7: 品牌需求
A8: 手绳 | B8: 563200 | C8: 品类需求
A9: 女 | B9: 545000 | C9: 人群需求
A10: 红绳 | B10: 516000 | C10: 品类需求
A11: 银 | B11: 451500 | C11: 属性需求
A12: 潘多拉 | B12: 415400 | C12: 品牌需求
A13: 女生 | B13: 401300 | C13: 人群需求
... A48: 手饰 | B48: 150300 | C48: 品类需求
A49: 2024 | B49: 149800 | C49: 风格需求
A50: 纪梵希 | B50: 147000 | C50: 品牌需求
A51: 白水晶 | B51: 145900 | C51: 属性需求
A52: 檀木 | B52: 136300 | C52: 属性需求
A53: 粉水晶 | B53: 129100 | C53: 属性需求
A54: 施华洛世奇 | B54: 125800 | C54: 品牌需求
A55: 配饰 | B55: 118400 | C55: 品类需求
A56: 判官 | B56: 108500 | C56: 功能功效
A57: 绿幽灵 | B57: 106200 | C57: 属性需求
A58: 五花 | B58: 102300 | C58: 风格需求
A59: 和田玉 | B59: 98400 | C59: 属性需求
A60: lv | B60: 97100 | C60: 品牌需求
A61: 月光石 | B61: 96700 | C61: 属性需求
... A96: 金发晶 | B96: 56600 | C96: 属性需求
A97: 999 | B97: 55800 | C97: 风格需求
A98: 貔貅 | B98: 55500 | C98: 属性需求
A99: 盘缠 | B99: 53100 | C99: 风格需求
A100: 穿 | B100: 53100 | C100: 场景需求
A101: 猫眼石 | B101: 52400 | C101: 属性需求
A102: 老凤祥 | B102: 51800 | C102: 品牌需求
A103: 草莓晶 | B103: 51400 | C103: 属性需求
A104: 鲸落 | B104: 51300 | C104: 风格需求
A105: 转运珠 | B105: 50000 | C105: 品类需求
A106: ins | B106: 48500 | C106: 风格需求
A107: 设计 | B107: 48500 | C107: 风格需求
A108: 转运 | B108: 47800 | C108: 功能功效
...

Sheet 八大需求词根归类分析报告
A1: 需求归类 | B1: 搜索人数 | C1: 需求占比 | D1: 分析报告
A2: 品类需求 | B2: =SUMIF('关键词需求归类'!C:C,A2,'关键词需求归类'!B:B) -> 21183164 | C2: =B2/SUM($B$2:$B$9) -> 0.50616803 | D2: 八大需求，最大的是品类词，也是搜索流量的体量词，具有极强的非标属性，客户自己也不知道想买什么样式的，需要逛和游览。其次是属性需求，类目的材质属性极多，主要以水晶玉石类为主，根据趋势分析，要规划在同人群下不同属性材质的趋势节点。人群的50%是女性人群，男性35%，但主词的女性人群占比70% 行业核心人群为女性人群 18-25占比47%
A3: 属性需求 | B3: =SUMIF('关键词需求归类'!C:C,A3,'关键词需求归类'!B:B) -> 9259517 | C3: =B3/SUM($B$2:$B$9) -> 0.22125455
A4: 人群需求 | B4: =SUMIF('关键词需求归类'!C:C,A4,'关键词需求归类'!B:B) -> 3167833 | C4: =B4/SUM($B$2:$B$9) -> 0.07569482
A5: 风格需求 | B5: =SUMIF('关键词需求归类'!C:C,A5,'关键词需求归类'!B:B) -> 3594445 | C5: =B5/SUM($B$2:$B$9) -> 0.08588864
A6: 场景需求 | B6: =SUMIF('关键词需求归类'!C:C,A6,'关键词需求归类'!B:B) -> 284400 | C6: =B6/SUM($B$2:$B$9) -> 0.0067956887
A7: 功能功效 | B7: =SUMIF('关键词需求归类'!C:C,A7,'关键词需求归类'!B:B) -> 787870 | C7: =B7/SUM($B$2:$B$9) -> 0.018826017
A8: 品牌需求 | B8: =SUMIF('关键词需求归类'!C:C,A8,'关键词需求归类'!B:B) -> 3515318 | C8: =B8/SUM($B$2:$B$9) -> 0.083997914
A9: 其他定制需求 | B9: =SUMIF('关键词需求归类'!C:C,A9,'关键词需求归类'!B:B) -> 57516 | C9: =B9/SUM($B$2:$B$9) -> 0.0013743348
A11: 需求归类 | B11: 词根 | C11: 搜索人数 | D11: 需求占比 | E11: 分析报告 | I11: 需求归类 | J11: 词根 | K11: 搜索人数 | L11: 需求占比 | M11: 分析报告
A12: 品类需求 | B12: 手链 | C12: 12344300 | D12: =IFERROR(C12/SUM($C$12:$C$21),"") -> 0.60227262 | E12: 手链，手串，红绳，串珠为主品类，手链和手串对比更年轻化一些，且消费力也低一些。手绳为趋势性词，主要在12-1月的新年节点 | I12: 属性需求 | J12: 朱砂 | K12: 1663700 | L12: =IFERROR(K12/SUM($K$12:$K$21),"") -> 0.29189768 | M12: 除朱砂外其他属性需求相对均匀，朱砂使用人群较广，主要集中在30-40岁之间。珍珠人群偏年轻。绿松石年龄30-50之间且高消费力。紫水晶在18-40之间有中偏高消费力。碧玺30-50高消费力人群，玛瑙25-50高消费力。石榴石20-40高消费。南红30-50高消费。黄水晶25-40高消费
B13: 手串 | C13: 5805400 | D13: =IFERROR(C13/SUM($C$12:$C$21),"") -> 0.28324275 | J13: 珍珠 | K13: 1034200 | L13: =IFERROR(K13/SUM($K$12:$K$21),"") -> 0.18145133
B14: 手绳 | C14: 563200 | D14: =IFERROR(C14/SUM($C$12:$C$21),"") -> 0.027478264 | J14: 水晶 | K14: 754900 | L14: =IFERROR(K14/SUM($K$12:$K$21),"") -> 0.13244789
B15: 红绳 | C15: 516000 | D15: =IFERROR(C15/SUM($C$12:$C$21),"") -> 0.025175398 | J15: 银 | K15: 451500 | L15: =IFERROR(K15/SUM($K$12:$K$21),"") -> 0.079216085
B16: 串珠 | C16: 377100 | D16: =IFERROR(C16/SUM($C$12:$C$21),"") -> 0.018398532 | J16: 绿松石 | K16: 352200 | L16: =IFERROR(K16/SUM($K$12:$K$21),"") -> 0.06179381
B17: 编织绳 | C17: 214500 | D17: =IFERROR(C17/SUM($C$12:$C$21),"") -> 0.010465355 | J17: 纯银 | K17: 339900 | L17: =IFERROR(K17/SUM($K$12:$K$21),"") -> 0.059635764
B18: 佛珠 | C18: 207600 | D18: =IFERROR(C18/SUM($C$12:$C$21),"") -> 0.010128707 | J18: 紫水晶 | K18: 295700 | L18: =IFERROR(K18/SUM($K$12:$K$21),"") -> 0.051880834
B19: 编绳 | C19: 165500 | D19: =IFERROR(C19/SUM($C$12:$C$21),"") -> 0.0080746675 | J19: 碧玺 | K19: 285500 | L19: =IFERROR(K19/SUM($K$12:$K$21),"") -> 0.050091234
B20: 手镯 | C20: 152300 | D20: =IFERROR(C20/SUM($C$12:$C$21),"") -> 0.0074306457 | J20: 黑曜石 | K20: 261400 | L20: =IFERROR(K20/SUM($K$12:$K$21),"") -> 0.045862868
B21: 手饰 | C21: 150300 | D21: =IFERROR(C21/SUM($C$12:$C$21),"") -> 0.0073330666 | J21: 玛瑙 | K21: 260600 | L21: =IFERROR(K21/SUM($K$12:$K$21),"") -> 0.045722507
B22: 配饰 | C22: 118400 | D22: =IFERROR(C22/SUM($C$12:$C$21),"") -> 0.0057766806 | J22: 石榴石 | K22: 248900 | L22: =IFERROR(K22/SUM($K$12:$K$21),"") -> 0.043669731
B23: 珠子 | C23: 95200 | D23: =IFERROR(C23/SUM($C$12:$C$21),"") -> 0.0046447634 | J23: 南红 | K23: 231600 | L23: =IFERROR(K23/SUM($K$12:$K$21),"") -> 0.04063443
B24: 玉 | C24: 84000 | D24: =IFERROR(C24/SUM($C$12:$C$21),"") -> 0.0040983207 | J24: 黄水晶 | K24: 201300 | L24: =IFERROR(K24/SUM($K$12:$K$21),"") -> 0.035318268
... B26: 红手绳 | C26: 60000 | D26: =IFERROR(C26/SUM($C$12:$C$21),"") -> 0.0029273719 | J26: 海蓝宝 | K26: 174600 | L26: =IFERROR(K26/SUM($K$12:$K$21),"") -> 0.030633729
A28: 需求归类 | B28: 词根 | C28: 搜索人数 | D28: 需求占比 | E28: 分析报告 | I28: 需求归类 | J28: 词根 | K28: 搜索人数 | L28: 需求占比 | M28: 分析报告
A29: 人群需求 | B29: 女 | C29: 545000 | D29: =IFERROR(C29/SUM($C$29:$C$38),"") -> 0.18635664 | E29: 女性人群为主，类目大词的人群占比基本在70%，且人群具有高消费力 | I29: 风格需求 | J29: 四叶草 | K29: 384600 | L29: =IFERROR(K29/SUM($K$29:$K$38),"") -> 0.17883381 | M29: 主体分为祝福类和小资轻奢类。
B30: 女生 | C30: 401300 | D30: =IFERROR(C30/SUM($C$29:$C$38),"") -> 0.13722004 | J30: 小众 | K30: 358100 | L30: =IFERROR(K30/SUM($K$29:$K$38),"") -> 0.16651167
B31: 女款 | C31: 400300 | D31: =IFERROR(C31/SUM($C$29:$C$38),"") -> 0.1368781 | J31: 天然 | K31: 296100 | L31: =IFERROR(K31/SUM($K$29:$K$38),"") -> 0.13768251
B32: 情侣 | C32: 381600 | D32: =IFERROR(C32/SUM($C$29:$C$38),"") -> 0.13048384 | J32: 精致 | K32: 235400 | L32: =IFERROR(K32/SUM($K$29:$K$38),"") -> 0.10945783
B33: 男士 | C33: 296600 | D33: =IFERROR(C33/SUM($C$29:$C$38),"") -> 0.10141905 | J33: 轻奢 | K33: 199700 | L33: =IFERROR(K33/SUM($K$29:$K$38),"") -> 0.092857807
B34: 男款 | C34: 293500 | D34: =IFERROR(C34/SUM($C$29:$C$38),"") -> 0.10035904 | J34: 新款 | K34: 171900 | L34: =IFERROR(K34/SUM($K$29:$K$38),"") -> 0.079931182
B35: 男生 | C35: 234800 | D35: =IFERROR(C35/SUM($C$29:$C$38),"") -> 0.080287229 | J35: 编织 | K35: 163600 | L35: =IFERROR(K35/SUM($K$29:$K$38),"") -> 0.076071794
B36: 男 | C36: 217300 | D36: =IFERROR(C36/SUM($C$29:$C$38),"") -> 0.0743033 | J36: 2024 | K36: 149800 | L36: =IFERROR(K36/SUM($K$29:$K$38),"") -> 0.06965498
B37: 闺蜜 | C37: 80600 | D37: =IFERROR(C37/SUM($C$29:$C$38),"") -> 0.027560267 | J37: 五花 | K37: 102300 | L37: =IFERROR(K37/SUM($K$29:$K$38),"") -> 0.047568121
B38: 儿童 | C38: 73500 | D38: =IFERROR(C38/SUM($C$29:$C$38),"") -> 0.025132501 | J38: 叠戴 | K38: 89100 | L38: =IFERROR(K38/SUM($K$29:$K$38),"") -> 0.041430299
B39: 女士 | C39: 67000 | D39: =IFERROR(C39/SUM($C$29:$C$38),"") -> 0.022909899 | J39: 一缕瓷 | K39: 86100 | L39: =IFERROR(K39/SUM($K$29:$K$38),"") -> 0.040035339
B40: 学生党 | C40: 64900 | D40: =IFERROR(C40/SUM($C$29:$C$38),"") -> 0.022191828 | J40: 运动感 | K40: 75000 | L40: =IFERROR(K40/SUM($K$29:$K$38),"") -> 0.034873989
B41: 一对 | C41: 28900 | D41: =IFERROR(C41/SUM($C$29:$C$38),"") -> 0.0098820311 | J41: 冷门 | K41: 70000 | L41: =IFERROR(K41/SUM($K$29:$K$38),"") -> 0.032549056
B42: 女孩 | C42: 20600 | D42: =IFERROR(C42/SUM($C$29:$C$38),"") -> 0.0070439391 | J42: 竹节 | K42: 69500 | L42: =IFERROR(K42/SUM($K$29:$K$38),"") -> 0.032316563
B43: 送女友 | C43: 16000 | D43: =IFERROR(C43/SUM($C$29:$C$38),"") -> 0.0054710207 | J43: 高颜值 | K43: 69400 | L43: =IFERROR(K43/SUM($K$29:$K$38),"") -> 0.032270064
...

Sheet 细分词分类报告
A1: Q2季度：7/8/9 产品布局
A2: 第二季度关键词趋势变化
A27: 结论 | B27: 夏季：7-8月虽然仍然有搜索，但是已经是下滑趋势，开款操作来不及，放弃 四季：6月底继续布链接，7-10月持续销售 冬季：10月出现了关键词高占位，9月就需要开始提前操作拉伸对应关键词的权重，8月进行产品开发和包装 防滑固定：8-10月都表现不错，需要具体分析，目前皮沙发专用有关联可以吃这个关键词的流量
A28: 2024年9月-沙发垫搜索8000+关键词需求分类
A29: 类目需求词 | B29: 排名 | C29: 关键词 | F29: 搜索指数 | G29: 支付指数 | H29: 需求
B30: 1 | C30: 沙发垫 | F30: 109.33万 | G30: 11.15万
B31: 2 | C31: 沙发盖布 | F31: 78.67万 | G31: 10.83万
B32: 3 | C32: 沙发套罩2024新款 | F32: 44.27万 | G32: 3.04万
B33: 4 | C33: 沙发巾 | F33: 22.19万 | G33: 2.92万 | H33: 沙发巾
B34: 5 | C34: 沙发坐垫 | F34: 18.56万 | G34: 1.36万
B35: 6 | C35: 沙发垫布 | F35: 13.66万 | G35: 1.63万
B36: 7 | C36: 沙发垫子 | F36: 12.18万 | G36: 9132
B37: 8 | C37: 沙发布 | F37: 11.92万 | G37: 1.75万
B38: 9 | C38: 沙发盖巾 | F38: 11.53万 | G38: 1.54万
B39: 10 | C39: 沙发垫固定防滑 | F39: 11.15万 | G39: 1.27万 | H39: 防滑
B40: 11 | C40: 沙发垫子2024新款四季通用 | F40: 11.14万 | G40: 9161 | H40: 四季
B41: 12 | C41: 沙发垫2024新款四季通用 | F41: 9.64万 | G41: 7327 | H41: 四季
B42: 13 | C42: 沙发垫四季通用2024新款 | F42: 9.41万 | G42: 8290 | H42: 四季
B43: 14 | C43: 沙发巾2024年流行新款 | F43: 8.63万 | G43: 6552 | H43: 沙发巾
B44: 15 | C44: 沙发巾一整张全盖 | F44: 8.56万 | G44: 8913 | H44: 沙发巾
B45: 16 | C45: 高密度海绵垫 | F45: 8.26万 | G45: 4547 | H45: 海绵
B46: 17 | C46: 沙发垫轻奢高级感 | F46: 7.63万 | G46: 7146 | H46: 轻奢高级
B47: 18 | C47: 沙发垫坐垫 | F47: 6.56万 | G47: 5334
B48: 19 | C48: 沙发垫四季通用 | F48: 6.52万 | G48: 1.32万 | H48: 四季
B49: 20 | C49: 沙发垫海绵垫 | F49: 6.51万 | G49: 4278 | H49: 海绵
B50: 21 | C50: 沙发四季通用垫 | F50: 5.40万 | G50: 4904 | H50: 四季
B51: 22 | C51: 沙发垫四季通用新款2024 | F51: 4.93万 | G51: 4353 | H51: 四季
B52: 23 | C52: 沙发垫轻奢高级感简约现代 | F52: 4.56万 | G52: 4263 | H52: 轻奢高级
B53: 24 | C53: 直排沙发垫 | F53: 4.27万 | G53: 1892
B54: 25 | C54: 高密度海绵 | F54: 3.92万 | G54: 3339 | H54: 海绵
B55: 26 | C55: 沙发垫子四季通用 | F55: 3.80万 | G55: 3711 | H55: 四季
B56: 27 | C56: 三座一贵妃沙发套 | F56: 3.43万 | G56: 2055 | H56: 三座一贵妃
B57: 28 | C57: 沙发巾盖布 | F57: 3.35万 | G57: 3594 | H57: 沙发巾
B58: 29 | C58: 沙发靠背盖巾 | F58: 3.18万 | G58: 4030
B59: 30 | C59: 沙发凉席垫 | F59: 2.60万 | G59: 3296
B60: 31 | C60: 沙发坐垫套罩 | F60: 2.46万 | G60: 3077
B61: 32 | C61: 四季通用沙发垫 | F61: 2.43万 | G61: 2489 | H61: 四季
B62: 33 | C62: 沙发套罩2024新款四季通用 | F62: 2.40万 | G62: 1858 | H62: 四季
B63: 34 | C63: 沙发套罩新款2024 | F63: 2.33万 | G63: 1818
B64: 35 | C64: 防滑沙发垫 | F64: 2.31万 | G64: 2608 | H64: 防滑
...
